[2022-01-11 18:47:01,730] {taskinstance.py:1032} INFO - Dependencies all met for <TaskInstance: my_dag.choose_best_model scheduled__2022-01-10T00:00:00+00:00 [queued]>
[2022-01-11 18:47:01,737] {taskinstance.py:1032} INFO - Dependencies all met for <TaskInstance: my_dag.choose_best_model scheduled__2022-01-10T00:00:00+00:00 [queued]>
[2022-01-11 18:47:01,737] {taskinstance.py:1238} INFO - 
--------------------------------------------------------------------------------
[2022-01-11 18:47:01,737] {taskinstance.py:1239} INFO - Starting attempt 1 of 1
[2022-01-11 18:47:01,737] {taskinstance.py:1240} INFO - 
--------------------------------------------------------------------------------
[2022-01-11 18:47:01,859] {taskinstance.py:1259} INFO - Executing <Task(BranchPythonOperator): choose_best_model> on 2022-01-10 00:00:00+00:00
[2022-01-11 18:47:01,862] {standard_task_runner.py:52} INFO - Started process 4384 to run task
[2022-01-11 18:47:01,868] {standard_task_runner.py:76} INFO - Running: ['***', 'tasks', 'run', 'my_dag', 'choose_best_model', 'scheduled__2022-01-10T00:00:00+00:00', '--job-id', '7', '--raw', '--subdir', 'DAGS_FOLDER/my_dag.py', '--cfg-path', '/tmp/tmp43i4c3pt', '--error-file', '/tmp/tmppr0072jw']
[2022-01-11 18:47:01,870] {standard_task_runner.py:77} INFO - Job 7: Subtask choose_best_model
[2022-01-11 18:47:01,972] {logging_mixin.py:109} INFO - Running <TaskInstance: my_dag.choose_best_model scheduled__2022-01-10T00:00:00+00:00 [running]> on host 40c4c8725776
[2022-01-11 18:47:02,151] {taskinstance.py:1426} INFO - Exporting the following env vars:
AIRFLOW_CTX_DAG_OWNER=***
AIRFLOW_CTX_DAG_ID=my_dag
AIRFLOW_CTX_TASK_ID=choose_best_model
AIRFLOW_CTX_EXECUTION_DATE=2022-01-10T00:00:00+00:00
AIRFLOW_CTX_DAG_RUN_ID=scheduled__2022-01-10T00:00:00+00:00
[2022-01-11 18:47:02,156] {taskinstance.py:1700} ERROR - Task failed with exception
Traceback (most recent call last):
  File "/home/airflow/.local/lib/python3.7/site-packages/airflow/models/taskinstance.py", line 1329, in _run_raw_task
    self._execute_task_with_callbacks(context)
  File "/home/airflow/.local/lib/python3.7/site-packages/airflow/models/taskinstance.py", line 1455, in _execute_task_with_callbacks
    result = self._execute_task(context, self.task)
  File "/home/airflow/.local/lib/python3.7/site-packages/airflow/models/taskinstance.py", line 1511, in _execute_task
    result = execute_callable(context=context)
  File "/home/airflow/.local/lib/python3.7/site-packages/airflow/operators/python.py", line 203, in execute
    branch = super().execute(context)
  File "/home/airflow/.local/lib/python3.7/site-packages/airflow/operators/python.py", line 174, in execute
    return_value = self.execute_callable()
  File "/home/airflow/.local/lib/python3.7/site-packages/airflow/operators/python.py", line 185, in execute_callable
    return self.python_callable(*self.op_args, **self.op_kwargs)
  File "/opt/airflow/dags/my_dag.py", line 14, in _choose_best_model
    best_accuracy = max(accuracies)
TypeError: '>' not supported between instances of 'NoneType' and 'NoneType'
[2022-01-11 18:47:02,165] {taskinstance.py:1277} INFO - Marking task as FAILED. dag_id=my_dag, task_id=choose_best_model, execution_date=20220110T000000, start_date=20220111T184701, end_date=20220111T184702
[2022-01-11 18:47:02,244] {standard_task_runner.py:92} ERROR - Failed to execute job 7 for task choose_best_model
Traceback (most recent call last):
  File "/home/airflow/.local/lib/python3.7/site-packages/airflow/task/task_runner/standard_task_runner.py", line 85, in _start_by_fork
    args.func(args, dag=self.dag)
  File "/home/airflow/.local/lib/python3.7/site-packages/airflow/cli/cli_parser.py", line 48, in command
    return func(*args, **kwargs)
  File "/home/airflow/.local/lib/python3.7/site-packages/airflow/utils/cli.py", line 92, in wrapper
    return f(*args, **kwargs)
  File "/home/airflow/.local/lib/python3.7/site-packages/airflow/cli/commands/task_command.py", line 298, in task_run
    _run_task_by_selected_method(args, dag, ti)
  File "/home/airflow/.local/lib/python3.7/site-packages/airflow/cli/commands/task_command.py", line 107, in _run_task_by_selected_method
    _run_raw_task(args, ti)
  File "/home/airflow/.local/lib/python3.7/site-packages/airflow/cli/commands/task_command.py", line 184, in _run_raw_task
    error_file=args.error_file,
  File "/home/airflow/.local/lib/python3.7/site-packages/airflow/utils/session.py", line 70, in wrapper
    return func(*args, session=session, **kwargs)
  File "/home/airflow/.local/lib/python3.7/site-packages/airflow/models/taskinstance.py", line 1329, in _run_raw_task
    self._execute_task_with_callbacks(context)
  File "/home/airflow/.local/lib/python3.7/site-packages/airflow/models/taskinstance.py", line 1455, in _execute_task_with_callbacks
    result = self._execute_task(context, self.task)
  File "/home/airflow/.local/lib/python3.7/site-packages/airflow/models/taskinstance.py", line 1511, in _execute_task
    result = execute_callable(context=context)
  File "/home/airflow/.local/lib/python3.7/site-packages/airflow/operators/python.py", line 203, in execute
    branch = super().execute(context)
  File "/home/airflow/.local/lib/python3.7/site-packages/airflow/operators/python.py", line 174, in execute
    return_value = self.execute_callable()
  File "/home/airflow/.local/lib/python3.7/site-packages/airflow/operators/python.py", line 185, in execute_callable
    return self.python_callable(*self.op_args, **self.op_kwargs)
  File "/opt/airflow/dags/my_dag.py", line 14, in _choose_best_model
    best_accuracy = max(accuracies)
TypeError: '>' not supported between instances of 'NoneType' and 'NoneType'
[2022-01-11 18:47:02,264] {local_task_job.py:154} INFO - Task exited with return code 1
[2022-01-11 18:47:02,361] {local_task_job.py:264} INFO - 0 downstream tasks scheduled from follow-on schedule check
[2022-01-11 18:54:03,592] {taskinstance.py:1032} INFO - Dependencies all met for <TaskInstance: my_dag.choose_best_model scheduled__2022-01-10T00:00:00+00:00 [queued]>
[2022-01-11 18:54:03,672] {taskinstance.py:1032} INFO - Dependencies all met for <TaskInstance: my_dag.choose_best_model scheduled__2022-01-10T00:00:00+00:00 [queued]>
[2022-01-11 18:54:03,672] {taskinstance.py:1238} INFO - 
--------------------------------------------------------------------------------
[2022-01-11 18:54:03,672] {taskinstance.py:1239} INFO - Starting attempt 1 of 1
[2022-01-11 18:54:03,672] {taskinstance.py:1240} INFO - 
--------------------------------------------------------------------------------
[2022-01-11 18:54:03,761] {taskinstance.py:1259} INFO - Executing <Task(BranchPythonOperator): choose_best_model> on 2022-01-10 00:00:00+00:00
[2022-01-11 18:54:03,764] {standard_task_runner.py:52} INFO - Started process 4676 to run task
[2022-01-11 18:54:03,769] {standard_task_runner.py:76} INFO - Running: ['***', 'tasks', 'run', 'my_dag', 'choose_best_model', 'scheduled__2022-01-10T00:00:00+00:00', '--job-id', '20', '--raw', '--subdir', 'DAGS_FOLDER/my_dag.py', '--cfg-path', '/tmp/tmprzfbx5e9', '--error-file', '/tmp/tmpwwd2simg']
[2022-01-11 18:54:03,769] {standard_task_runner.py:77} INFO - Job 20: Subtask choose_best_model
[2022-01-11 18:54:03,884] {logging_mixin.py:109} INFO - Running <TaskInstance: my_dag.choose_best_model scheduled__2022-01-10T00:00:00+00:00 [running]> on host 40c4c8725776
[2022-01-11 18:54:04,019] {taskinstance.py:1426} INFO - Exporting the following env vars:
AIRFLOW_CTX_DAG_OWNER=***
AIRFLOW_CTX_DAG_ID=my_dag
AIRFLOW_CTX_TASK_ID=choose_best_model
AIRFLOW_CTX_EXECUTION_DATE=2022-01-10T00:00:00+00:00
AIRFLOW_CTX_DAG_RUN_ID=scheduled__2022-01-10T00:00:00+00:00
[2022-01-11 18:54:04,026] {python.py:175} INFO - Done. Returned value was: <Task(BashOperator): accurate>
[2022-01-11 18:54:04,034] {taskinstance.py:1700} ERROR - Task failed with exception
Traceback (most recent call last):
  File "/home/airflow/.local/lib/python3.7/site-packages/airflow/models/taskinstance.py", line 1329, in _run_raw_task
    self._execute_task_with_callbacks(context)
  File "/home/airflow/.local/lib/python3.7/site-packages/airflow/models/taskinstance.py", line 1455, in _execute_task_with_callbacks
    result = self._execute_task(context, self.task)
  File "/home/airflow/.local/lib/python3.7/site-packages/airflow/models/taskinstance.py", line 1511, in _execute_task
    result = execute_callable(context=context)
  File "/home/airflow/.local/lib/python3.7/site-packages/airflow/operators/python.py", line 210, in execute
    raise AirflowException("Branch callable must return either a task ID or a list of IDs")
airflow.exceptions.AirflowException: Branch callable must return either a task ID or a list of IDs
[2022-01-11 18:54:04,040] {taskinstance.py:1277} INFO - Marking task as FAILED. dag_id=my_dag, task_id=choose_best_model, execution_date=20220110T000000, start_date=20220111T185403, end_date=20220111T185404
[2022-01-11 18:54:04,136] {standard_task_runner.py:92} ERROR - Failed to execute job 20 for task choose_best_model
Traceback (most recent call last):
  File "/home/airflow/.local/lib/python3.7/site-packages/airflow/task/task_runner/standard_task_runner.py", line 85, in _start_by_fork
    args.func(args, dag=self.dag)
  File "/home/airflow/.local/lib/python3.7/site-packages/airflow/cli/cli_parser.py", line 48, in command
    return func(*args, **kwargs)
  File "/home/airflow/.local/lib/python3.7/site-packages/airflow/utils/cli.py", line 92, in wrapper
    return f(*args, **kwargs)
  File "/home/airflow/.local/lib/python3.7/site-packages/airflow/cli/commands/task_command.py", line 298, in task_run
    _run_task_by_selected_method(args, dag, ti)
  File "/home/airflow/.local/lib/python3.7/site-packages/airflow/cli/commands/task_command.py", line 107, in _run_task_by_selected_method
    _run_raw_task(args, ti)
  File "/home/airflow/.local/lib/python3.7/site-packages/airflow/cli/commands/task_command.py", line 184, in _run_raw_task
    error_file=args.error_file,
  File "/home/airflow/.local/lib/python3.7/site-packages/airflow/utils/session.py", line 70, in wrapper
    return func(*args, session=session, **kwargs)
  File "/home/airflow/.local/lib/python3.7/site-packages/airflow/models/taskinstance.py", line 1329, in _run_raw_task
    self._execute_task_with_callbacks(context)
  File "/home/airflow/.local/lib/python3.7/site-packages/airflow/models/taskinstance.py", line 1455, in _execute_task_with_callbacks
    result = self._execute_task(context, self.task)
  File "/home/airflow/.local/lib/python3.7/site-packages/airflow/models/taskinstance.py", line 1511, in _execute_task
    result = execute_callable(context=context)
  File "/home/airflow/.local/lib/python3.7/site-packages/airflow/operators/python.py", line 210, in execute
    raise AirflowException("Branch callable must return either a task ID or a list of IDs")
airflow.exceptions.AirflowException: Branch callable must return either a task ID or a list of IDs
[2022-01-11 18:54:04,172] {local_task_job.py:154} INFO - Task exited with return code 1
[2022-01-11 18:54:04,261] {local_task_job.py:264} INFO - 0 downstream tasks scheduled from follow-on schedule check
