[2022-01-11 18:47:40,489] {taskinstance.py:1032} INFO - Dependencies all met for <TaskInstance: my_dag.training_model_B manual__2022-01-11T18:47:36.508224+00:00 [queued]>
[2022-01-11 18:47:40,553] {taskinstance.py:1032} INFO - Dependencies all met for <TaskInstance: my_dag.training_model_B manual__2022-01-11T18:47:36.508224+00:00 [queued]>
[2022-01-11 18:47:40,557] {taskinstance.py:1238} INFO - 
--------------------------------------------------------------------------------
[2022-01-11 18:47:40,557] {taskinstance.py:1239} INFO - Starting attempt 1 of 1
[2022-01-11 18:47:40,557] {taskinstance.py:1240} INFO - 
--------------------------------------------------------------------------------
[2022-01-11 18:47:40,723] {taskinstance.py:1259} INFO - Executing <Task(PythonOperator): training_model_B> on 2022-01-11 18:47:36.508224+00:00
[2022-01-11 18:47:40,726] {standard_task_runner.py:52} INFO - Started process 4417 to run task
[2022-01-11 18:47:40,773] {standard_task_runner.py:76} INFO - Running: ['***', 'tasks', 'run', 'my_dag', 'training_model_B', 'manual__2022-01-11T18:47:36.508224+00:00', '--job-id', '10', '--raw', '--subdir', 'DAGS_FOLDER/my_dag.py', '--cfg-path', '/tmp/tmpji3i3znx', '--error-file', '/tmp/tmpj_7hpn2w']
[2022-01-11 18:47:40,830] {standard_task_runner.py:77} INFO - Job 10: Subtask training_model_B
[2022-01-11 18:47:41,735] {logging_mixin.py:109} INFO - Running <TaskInstance: my_dag.training_model_B manual__2022-01-11T18:47:36.508224+00:00 [running]> on host 40c4c8725776
[2022-01-11 18:47:42,387] {taskinstance.py:1426} INFO - Exporting the following env vars:
AIRFLOW_CTX_DAG_OWNER=***
AIRFLOW_CTX_DAG_ID=my_dag
AIRFLOW_CTX_TASK_ID=training_model_B
AIRFLOW_CTX_EXECUTION_DATE=2022-01-11T18:47:36.508224+00:00
AIRFLOW_CTX_DAG_RUN_ID=manual__2022-01-11T18:47:36.508224+00:00
[2022-01-11 18:47:42,389] {taskinstance.py:1700} ERROR - Task failed with exception
Traceback (most recent call last):
  File "/home/airflow/.local/lib/python3.7/site-packages/airflow/models/taskinstance.py", line 1329, in _run_raw_task
    self._execute_task_with_callbacks(context)
  File "/home/airflow/.local/lib/python3.7/site-packages/airflow/models/taskinstance.py", line 1455, in _execute_task_with_callbacks
    result = self._execute_task(context, self.task)
  File "/home/airflow/.local/lib/python3.7/site-packages/airflow/models/taskinstance.py", line 1511, in _execute_task
    result = execute_callable(context=context)
  File "/home/airflow/.local/lib/python3.7/site-packages/airflow/operators/python.py", line 174, in execute
    return_value = self.execute_callable()
  File "/home/airflow/.local/lib/python3.7/site-packages/airflow/operators/python.py", line 185, in execute_callable
    return self.python_callable(*self.op_args, **self.op_kwargs)
  File "/opt/airflow/dags/my_dag.py", line 21, in _training_model
    return randint(1,10)
NameError: name 'randint' is not defined
[2022-01-11 18:47:42,457] {taskinstance.py:1277} INFO - Marking task as FAILED. dag_id=my_dag, task_id=training_model_B, execution_date=20220111T184736, start_date=20220111T184740, end_date=20220111T184742
[2022-01-11 18:47:42,598] {standard_task_runner.py:92} ERROR - Failed to execute job 10 for task training_model_B
Traceback (most recent call last):
  File "/home/airflow/.local/lib/python3.7/site-packages/airflow/task/task_runner/standard_task_runner.py", line 85, in _start_by_fork
    args.func(args, dag=self.dag)
  File "/home/airflow/.local/lib/python3.7/site-packages/airflow/cli/cli_parser.py", line 48, in command
    return func(*args, **kwargs)
  File "/home/airflow/.local/lib/python3.7/site-packages/airflow/utils/cli.py", line 92, in wrapper
    return f(*args, **kwargs)
  File "/home/airflow/.local/lib/python3.7/site-packages/airflow/cli/commands/task_command.py", line 298, in task_run
    _run_task_by_selected_method(args, dag, ti)
  File "/home/airflow/.local/lib/python3.7/site-packages/airflow/cli/commands/task_command.py", line 107, in _run_task_by_selected_method
    _run_raw_task(args, ti)
  File "/home/airflow/.local/lib/python3.7/site-packages/airflow/cli/commands/task_command.py", line 184, in _run_raw_task
    error_file=args.error_file,
  File "/home/airflow/.local/lib/python3.7/site-packages/airflow/utils/session.py", line 70, in wrapper
    return func(*args, session=session, **kwargs)
  File "/home/airflow/.local/lib/python3.7/site-packages/airflow/models/taskinstance.py", line 1329, in _run_raw_task
    self._execute_task_with_callbacks(context)
  File "/home/airflow/.local/lib/python3.7/site-packages/airflow/models/taskinstance.py", line 1455, in _execute_task_with_callbacks
    result = self._execute_task(context, self.task)
  File "/home/airflow/.local/lib/python3.7/site-packages/airflow/models/taskinstance.py", line 1511, in _execute_task
    result = execute_callable(context=context)
  File "/home/airflow/.local/lib/python3.7/site-packages/airflow/operators/python.py", line 174, in execute
    return_value = self.execute_callable()
  File "/home/airflow/.local/lib/python3.7/site-packages/airflow/operators/python.py", line 185, in execute_callable
    return self.python_callable(*self.op_args, **self.op_kwargs)
  File "/opt/airflow/dags/my_dag.py", line 21, in _training_model
    return randint(1,10)
NameError: name 'randint' is not defined
[2022-01-11 18:47:42,652] {local_task_job.py:154} INFO - Task exited with return code 1
[2022-01-11 18:47:42,806] {local_task_job.py:264} INFO - 0 downstream tasks scheduled from follow-on schedule check
