[2022-01-11 18:46:12,400] {taskinstance.py:1032} INFO - Dependencies all met for <TaskInstance: my_dag.training_model_A scheduled__2022-01-10T00:00:00+00:00 [queued]>
[2022-01-11 18:46:12,406] {taskinstance.py:1032} INFO - Dependencies all met for <TaskInstance: my_dag.training_model_A scheduled__2022-01-10T00:00:00+00:00 [queued]>
[2022-01-11 18:46:12,406] {taskinstance.py:1238} INFO - 
--------------------------------------------------------------------------------
[2022-01-11 18:46:12,406] {taskinstance.py:1239} INFO - Starting attempt 2 of 2
[2022-01-11 18:46:12,406] {taskinstance.py:1240} INFO - 
--------------------------------------------------------------------------------
[2022-01-11 18:46:12,531] {taskinstance.py:1259} INFO - Executing <Task(PythonOperator): training_model_A> on 2022-01-10 00:00:00+00:00
[2022-01-11 18:46:12,534] {standard_task_runner.py:52} INFO - Started process 4347 to run task
[2022-01-11 18:46:12,551] {standard_task_runner.py:76} INFO - Running: ['***', 'tasks', 'run', 'my_dag', 'training_model_A', 'scheduled__2022-01-10T00:00:00+00:00', '--job-id', '6', '--raw', '--subdir', 'DAGS_FOLDER/my_dag.py', '--cfg-path', '/tmp/tmp6z52oz81', '--error-file', '/tmp/tmpdk_uhl4o']
[2022-01-11 18:46:12,551] {standard_task_runner.py:77} INFO - Job 6: Subtask training_model_A
[2022-01-11 18:46:12,654] {logging_mixin.py:109} INFO - Running <TaskInstance: my_dag.training_model_A scheduled__2022-01-10T00:00:00+00:00 [running]> on host 40c4c8725776
[2022-01-11 18:46:12,781] {taskinstance.py:1426} INFO - Exporting the following env vars:
AIRFLOW_CTX_DAG_OWNER=***
AIRFLOW_CTX_DAG_ID=my_dag
AIRFLOW_CTX_TASK_ID=training_model_A
AIRFLOW_CTX_EXECUTION_DATE=2022-01-10T00:00:00+00:00
AIRFLOW_CTX_DAG_RUN_ID=scheduled__2022-01-10T00:00:00+00:00
[2022-01-11 18:46:12,782] {taskinstance.py:1700} ERROR - Task failed with exception
Traceback (most recent call last):
  File "/home/airflow/.local/lib/python3.7/site-packages/airflow/models/taskinstance.py", line 1329, in _run_raw_task
    self._execute_task_with_callbacks(context)
  File "/home/airflow/.local/lib/python3.7/site-packages/airflow/models/taskinstance.py", line 1455, in _execute_task_with_callbacks
    result = self._execute_task(context, self.task)
  File "/home/airflow/.local/lib/python3.7/site-packages/airflow/models/taskinstance.py", line 1511, in _execute_task
    result = execute_callable(context=context)
  File "/home/airflow/.local/lib/python3.7/site-packages/airflow/operators/python.py", line 174, in execute
    return_value = self.execute_callable()
  File "/home/airflow/.local/lib/python3.7/site-packages/airflow/operators/python.py", line 185, in execute_callable
    return self.python_callable(*self.op_args, **self.op_kwargs)
  File "/opt/airflow/dags/my_dag.py", line 21, in _training_model
    return randint(1,10)
NameError: name 'randint' is not defined
[2022-01-11 18:46:12,791] {taskinstance.py:1277} INFO - Marking task as FAILED. dag_id=my_dag, task_id=training_model_A, execution_date=20220110T000000, start_date=20220111T184612, end_date=20220111T184612
[2022-01-11 18:46:12,866] {standard_task_runner.py:92} ERROR - Failed to execute job 6 for task training_model_A
Traceback (most recent call last):
  File "/home/airflow/.local/lib/python3.7/site-packages/airflow/task/task_runner/standard_task_runner.py", line 85, in _start_by_fork
    args.func(args, dag=self.dag)
  File "/home/airflow/.local/lib/python3.7/site-packages/airflow/cli/cli_parser.py", line 48, in command
    return func(*args, **kwargs)
  File "/home/airflow/.local/lib/python3.7/site-packages/airflow/utils/cli.py", line 92, in wrapper
    return f(*args, **kwargs)
  File "/home/airflow/.local/lib/python3.7/site-packages/airflow/cli/commands/task_command.py", line 298, in task_run
    _run_task_by_selected_method(args, dag, ti)
  File "/home/airflow/.local/lib/python3.7/site-packages/airflow/cli/commands/task_command.py", line 107, in _run_task_by_selected_method
    _run_raw_task(args, ti)
  File "/home/airflow/.local/lib/python3.7/site-packages/airflow/cli/commands/task_command.py", line 184, in _run_raw_task
    error_file=args.error_file,
  File "/home/airflow/.local/lib/python3.7/site-packages/airflow/utils/session.py", line 70, in wrapper
    return func(*args, session=session, **kwargs)
  File "/home/airflow/.local/lib/python3.7/site-packages/airflow/models/taskinstance.py", line 1329, in _run_raw_task
    self._execute_task_with_callbacks(context)
  File "/home/airflow/.local/lib/python3.7/site-packages/airflow/models/taskinstance.py", line 1455, in _execute_task_with_callbacks
    result = self._execute_task(context, self.task)
  File "/home/airflow/.local/lib/python3.7/site-packages/airflow/models/taskinstance.py", line 1511, in _execute_task
    result = execute_callable(context=context)
  File "/home/airflow/.local/lib/python3.7/site-packages/airflow/operators/python.py", line 174, in execute
    return_value = self.execute_callable()
  File "/home/airflow/.local/lib/python3.7/site-packages/airflow/operators/python.py", line 185, in execute_callable
    return self.python_callable(*self.op_args, **self.op_kwargs)
  File "/opt/airflow/dags/my_dag.py", line 21, in _training_model
    return randint(1,10)
NameError: name 'randint' is not defined
[2022-01-11 18:46:12,871] {local_task_job.py:154} INFO - Task exited with return code 1
[2022-01-11 18:46:12,948] {local_task_job.py:264} INFO - 0 downstream tasks scheduled from follow-on schedule check
[2022-01-11 18:53:49,533] {taskinstance.py:1032} INFO - Dependencies all met for <TaskInstance: my_dag.training_model_A scheduled__2022-01-10T00:00:00+00:00 [queued]>
[2022-01-11 18:53:49,586] {taskinstance.py:1032} INFO - Dependencies all met for <TaskInstance: my_dag.training_model_A scheduled__2022-01-10T00:00:00+00:00 [queued]>
[2022-01-11 18:53:49,587] {taskinstance.py:1238} INFO - 
--------------------------------------------------------------------------------
[2022-01-11 18:53:49,587] {taskinstance.py:1239} INFO - Starting attempt 2 of 2
[2022-01-11 18:53:49,587] {taskinstance.py:1240} INFO - 
--------------------------------------------------------------------------------
[2022-01-11 18:53:49,721] {taskinstance.py:1259} INFO - Executing <Task(PythonOperator): training_model_A> on 2022-01-10 00:00:00+00:00
[2022-01-11 18:53:49,725] {standard_task_runner.py:52} INFO - Started process 4661 to run task
[2022-01-11 18:53:49,730] {standard_task_runner.py:76} INFO - Running: ['***', 'tasks', 'run', 'my_dag', 'training_model_A', 'scheduled__2022-01-10T00:00:00+00:00', '--job-id', '17', '--raw', '--subdir', 'DAGS_FOLDER/my_dag.py', '--cfg-path', '/tmp/tmpfmkwxmbm', '--error-file', '/tmp/tmpn0oic_4v']
[2022-01-11 18:53:49,731] {standard_task_runner.py:77} INFO - Job 17: Subtask training_model_A
[2022-01-11 18:53:49,851] {logging_mixin.py:109} INFO - Running <TaskInstance: my_dag.training_model_A scheduled__2022-01-10T00:00:00+00:00 [running]> on host 40c4c8725776
[2022-01-11 18:53:49,954] {taskinstance.py:1426} INFO - Exporting the following env vars:
AIRFLOW_CTX_DAG_OWNER=***
AIRFLOW_CTX_DAG_ID=my_dag
AIRFLOW_CTX_TASK_ID=training_model_A
AIRFLOW_CTX_EXECUTION_DATE=2022-01-10T00:00:00+00:00
AIRFLOW_CTX_DAG_RUN_ID=scheduled__2022-01-10T00:00:00+00:00
[2022-01-11 18:53:49,955] {python.py:175} INFO - Done. Returned value was: 10
[2022-01-11 18:53:50,048] {taskinstance.py:1277} INFO - Marking task as SUCCESS. dag_id=my_dag, task_id=training_model_A, execution_date=20220110T000000, start_date=20220111T185349, end_date=20220111T185350
[2022-01-11 18:53:50,126] {local_task_job.py:154} INFO - Task exited with return code 0
[2022-01-11 18:53:50,268] {local_task_job.py:264} INFO - 0 downstream tasks scheduled from follow-on schedule check
